2022-05-16 20:21:30,652 [INFO] root consoleworker.py:434	Log file created
2022-05-16 20:21:30,654 [INFO] root consoleworker.py:438	Logging handler <logging.FileHandler object at 0x40192a2c10> added
2022-05-16 20:21:30,655 [INFO] root consoleworker.py:438	Logging handler <logging.StreamHandler object at 0x401926a850> added
2022-05-16 20:21:30,658 [INFO] root consoleworker.py:438	Logging handler <logging.StreamHandler object at 0x401928ea50> added
2022-05-16 20:21:30,659 [INFO] root consoleworker.py:373	Created a folder for the test. /var/loadtest/logs/2022-05-16_20-21-30.471649
2022-05-16 20:21:30,661 [INFO] yandextank.core.tankcore tankcore.py:237	Configuring plugins...
2022-05-16 20:21:30,662 [INFO] yandextank.core.tankcore tankcore.py:190	Loading plugins...
2022-05-16 20:21:30,664 [DEBUG] yandextank.core.tankcore tankcore.py:192	Loading plugin phantom from yandextank.plugins.Phantom
2022-05-16 20:21:30,665 [DEBUG] yandextank.core.tankcore tankcore.py:192	Loading plugin rcheck from yandextank.plugins.ResourceCheck
2022-05-16 20:21:30,666 [DEBUG] yandextank.core.tankcore tankcore.py:192	Loading plugin json_report from yandextank.plugins.JsonReport
2022-05-16 20:21:30,680 [DEBUG] yandextank.core.tankcore tankcore.py:192	Loading plugin overload from yandextank.plugins.DataUploader
2022-05-16 20:21:30,683 [DEBUG] yandextank.core.tankcore tankcore.py:192	Loading plugin rcassert from yandextank.plugins.RCAssert
2022-05-16 20:21:30,684 [DEBUG] yandextank.core.tankcore tankcore.py:192	Loading plugin console from yandextank.plugins.Console
2022-05-16 20:21:30,685 [DEBUG] yandextank.core.tankcore tankcore.py:192	Loading plugin shellexec from yandextank.plugins.ShellExec
2022-05-16 20:21:30,686 [DEBUG] yandextank.core.tankcore tankcore.py:192	Loading plugin autostop from yandextank.plugins.Autostop
2022-05-16 20:21:30,689 [DEBUG] yandextank.core.tankcore tankcore.py:212	Plugin instances: {'plugin_phantom': <yandextank.plugins.Phantom.plugin.Plugin object at 0x401959ff50>, 'plugin_autostop': <yandextank.plugins.Autostop.plugin.Plugin object at 0x40195b11d0>, 'plugin_shellexec': <yandextank.plugins.ShellExec.plugin.Plugin object at 0x40195b10d0>, 'plugin_console': <yandextank.plugins.Console.plugin.Plugin object at 0x40195b1550>, 'plugin_rcassert': <yandextank.plugins.RCAssert.plugin.Plugin object at 0x40195b1050>, 'plugin_rcheck': <yandextank.plugins.ResourceCheck.plugin.Plugin object at 0x401959fe50>, 'plugin_overload': <yandextank.plugins.DataUploader.plugin.Plugin object at 0x401959fb10>, 'plugin_json_report': <yandextank.plugins.JsonReport.plugin.Plugin object at 0x401920aa10>}
2022-05-16 20:21:30,692 [DEBUG] yandextank.core.tankcore tankcore.py:244	Configuring <yandextank.plugins.Phantom.plugin.Plugin object at 0x401959ff50>
2022-05-16 20:21:30,694 [DEBUG] yandextank.core.tankcore tankcore.py:391	Searching for plugin: <class 'yandextank.plugins.Autostop.plugin.Plugin'>
2022-05-16 20:21:30,708 [DEBUG] yandextank.core.tankcore tankcore.py:446	Adding artifact file to collect (keep=False): /var/loadtest/logs/2022-05-16_20-21-30.471649/answ_vw2VFK.log
2022-05-16 20:21:30,715 [DEBUG] yandextank.core.tankcore tankcore.py:446	Adding artifact file to collect (keep=False): /var/loadtest/logs/2022-05-16_20-21-30.471649/phout_piPd7l.log
2022-05-16 20:21:30,716 [DEBUG] yandextank.core.tankcore tankcore.py:446	Adding artifact file to collect (keep=False): /var/loadtest/logs/2022-05-16_20-21-30.471649/phantom_stat_tfUPGY.log
2022-05-16 20:21:30,723 [DEBUG] yandextank.core.tankcore tankcore.py:446	Adding artifact file to collect (keep=False): /var/loadtest/logs/2022-05-16_20-21-30.471649/phantom_07W8th.log
2022-05-16 20:21:30,725 [DEBUG] yandextank.common.util util.py:479	Trying to resolve address string: localhost:8080
2022-05-16 20:21:30,730 [DEBUG] yandextank.common.util util.py:516	Parsing port
2022-05-16 20:21:30,738 [DEBUG] yandextank.common.util util.py:527	Lookup result: [(2, 1, 6, '', ('127.0.0.1', 8080)), (2, 2, 17, '', ('127.0.0.1', 8080)), (2, 3, 0, '', ('127.0.0.1', 8080)), (10, 1, 6, '', ('::1', 8080, 0, 0)), (10, 2, 17, '', ('::1', 8080, 0, 0)), (10, 3, 0, '', ('::1', 8080, 0, 0))]
2022-05-16 20:21:30,741 [INFO] yandextank.common.util util.py:546	Testing connection to resolved address 127.0.0.1 and port 8080
2022-05-16 20:21:30,746 [DEBUG] yandextank.common.util util.py:565	Exception on connect attempt [127.0.0.1]:8080 : Traceback (most recent call last):
  File "/usr/local/lib/python2.7/dist-packages/yandextank/common/util.py", line 561, in __test
    test_sock.connect(sa)
  File "/usr/lib/python2.7/socket.py", line 228, in meth
    return getattr(self._sock,name)(*args)
error: [Errno 111] Connection refused

2022-05-16 20:21:30,748 [INFO] yandextank.common.util util.py:549	Failed TCP connection test using [127.0.0.1]:8080
2022-05-16 20:21:30,749 [DEBUG] yandextank.common.util util.py:550	Failed TCP connection test using [127.0.0.1]:8080
Traceback (most recent call last):
  File "/usr/local/lib/python2.7/dist-packages/yandextank/common/util.py", line 547, in resolve
    self.__test(family, (parsed_ip, port))
  File "/usr/local/lib/python2.7/dist-packages/yandextank/common/util.py", line 567, in __test
    raise RuntimeError(msg % (sa[0], sa[1]))
RuntimeError: TCP Connection test failed for [127.0.0.1]:8080, use phantom.connection_test=0 to disable it
2022-05-16 20:21:30,750 [INFO] yandextank.common.util util.py:546	Testing connection to resolved address 127.0.0.1 and port 8080
2022-05-16 20:21:30,752 [DEBUG] yandextank.common.util util.py:565	Exception on connect attempt [127.0.0.1]:8080 : Traceback (most recent call last):
  File "/usr/local/lib/python2.7/dist-packages/yandextank/common/util.py", line 561, in __test
    test_sock.connect(sa)
  File "/usr/lib/python2.7/socket.py", line 228, in meth
    return getattr(self._sock,name)(*args)
error: [Errno 111] Connection refused

2022-05-16 20:21:30,755 [INFO] yandextank.common.util util.py:549	Failed TCP connection test using [127.0.0.1]:8080
2022-05-16 20:21:30,759 [DEBUG] yandextank.common.util util.py:550	Failed TCP connection test using [127.0.0.1]:8080
Traceback (most recent call last):
  File "/usr/local/lib/python2.7/dist-packages/yandextank/common/util.py", line 547, in resolve
    self.__test(family, (parsed_ip, port))
  File "/usr/local/lib/python2.7/dist-packages/yandextank/common/util.py", line 567, in __test
    raise RuntimeError(msg % (sa[0], sa[1]))
RuntimeError: TCP Connection test failed for [127.0.0.1]:8080, use phantom.connection_test=0 to disable it
2022-05-16 20:21:30,763 [INFO] yandextank.common.util util.py:546	Testing connection to resolved address 127.0.0.1 and port 8080
2022-05-16 20:21:30,766 [DEBUG] yandextank.common.util util.py:565	Exception on connect attempt [127.0.0.1]:8080 : Traceback (most recent call last):
  File "/usr/local/lib/python2.7/dist-packages/yandextank/common/util.py", line 561, in __test
    test_sock.connect(sa)
  File "/usr/lib/python2.7/socket.py", line 228, in meth
    return getattr(self._sock,name)(*args)
error: [Errno 111] Connection refused

2022-05-16 20:21:30,768 [INFO] yandextank.common.util util.py:549	Failed TCP connection test using [127.0.0.1]:8080
2022-05-16 20:21:30,769 [DEBUG] yandextank.common.util util.py:550	Failed TCP connection test using [127.0.0.1]:8080
Traceback (most recent call last):
  File "/usr/local/lib/python2.7/dist-packages/yandextank/common/util.py", line 547, in resolve
    self.__test(family, (parsed_ip, port))
  File "/usr/local/lib/python2.7/dist-packages/yandextank/common/util.py", line 567, in __test
    raise RuntimeError(msg % (sa[0], sa[1]))
RuntimeError: TCP Connection test failed for [127.0.0.1]:8080, use phantom.connection_test=0 to disable it
2022-05-16 20:21:30,770 [INFO] yandextank.common.util util.py:546	Testing connection to resolved address ::1 and port 8080
2022-05-16 20:21:30,772 [DEBUG] yandextank.common.util util.py:565	Exception on connect attempt [::1]:8080 : Traceback (most recent call last):
  File "/usr/local/lib/python2.7/dist-packages/yandextank/common/util.py", line 561, in __test
    test_sock.connect(sa)
  File "/usr/lib/python2.7/socket.py", line 228, in meth
    return getattr(self._sock,name)(*args)
error: [Errno 99] Cannot assign requested address

2022-05-16 20:21:30,775 [INFO] yandextank.common.util util.py:549	Failed TCP connection test using [::1]:8080
2022-05-16 20:21:30,779 [DEBUG] yandextank.common.util util.py:550	Failed TCP connection test using [::1]:8080
Traceback (most recent call last):
  File "/usr/local/lib/python2.7/dist-packages/yandextank/common/util.py", line 547, in resolve
    self.__test(family, (parsed_ip, port))
  File "/usr/local/lib/python2.7/dist-packages/yandextank/common/util.py", line 567, in __test
    raise RuntimeError(msg % (sa[0], sa[1]))
RuntimeError: TCP Connection test failed for [::1]:8080, use phantom.connection_test=0 to disable it
2022-05-16 20:21:30,781 [INFO] yandextank.common.util util.py:546	Testing connection to resolved address ::1 and port 8080
2022-05-16 20:21:30,784 [DEBUG] yandextank.common.util util.py:565	Exception on connect attempt [::1]:8080 : Traceback (most recent call last):
  File "/usr/local/lib/python2.7/dist-packages/yandextank/common/util.py", line 561, in __test
    test_sock.connect(sa)
  File "/usr/lib/python2.7/socket.py", line 228, in meth
    return getattr(self._sock,name)(*args)
error: [Errno 99] Cannot assign requested address

2022-05-16 20:21:30,786 [INFO] yandextank.common.util util.py:549	Failed TCP connection test using [::1]:8080
2022-05-16 20:21:30,788 [DEBUG] yandextank.common.util util.py:550	Failed TCP connection test using [::1]:8080
Traceback (most recent call last):
  File "/usr/local/lib/python2.7/dist-packages/yandextank/common/util.py", line 547, in resolve
    self.__test(family, (parsed_ip, port))
  File "/usr/local/lib/python2.7/dist-packages/yandextank/common/util.py", line 567, in __test
    raise RuntimeError(msg % (sa[0], sa[1]))
RuntimeError: TCP Connection test failed for [::1]:8080, use phantom.connection_test=0 to disable it
2022-05-16 20:21:30,792 [INFO] yandextank.common.util util.py:546	Testing connection to resolved address ::1 and port 8080
2022-05-16 20:21:30,798 [DEBUG] yandextank.common.util util.py:565	Exception on connect attempt [::1]:8080 : Traceback (most recent call last):
  File "/usr/local/lib/python2.7/dist-packages/yandextank/common/util.py", line 561, in __test
    test_sock.connect(sa)
  File "/usr/lib/python2.7/socket.py", line 228, in meth
    return getattr(self._sock,name)(*args)
error: [Errno 99] Cannot assign requested address

2022-05-16 20:21:30,801 [INFO] yandextank.common.util util.py:549	Failed TCP connection test using [::1]:8080
2022-05-16 20:21:30,802 [DEBUG] yandextank.common.util util.py:550	Failed TCP connection test using [::1]:8080
Traceback (most recent call last):
  File "/usr/local/lib/python2.7/dist-packages/yandextank/common/util.py", line 547, in resolve
    self.__test(family, (parsed_ip, port))
  File "/usr/local/lib/python2.7/dist-packages/yandextank/common/util.py", line 567, in __test
    raise RuntimeError(msg % (sa[0], sa[1]))
RuntimeError: TCP Connection test failed for [::1]:8080, use phantom.connection_test=0 to disable it
2022-05-16 20:21:30,807 [ERROR] root consoleworker.py:268	Exception occurred:
<type 'exceptions.RuntimeError'>: All connection attempts failed for localhost, use {phantom.connection_test: false} to disable it
  File "/usr/local/lib/python2.7/dist-packages/yandextank/core/consoleworker.py", line 375, in run
    self.core.plugins_configure()

  File "/usr/local/lib/python2.7/dist-packages/yandextank/core/tankcore.py", line 245, in plugins_configure
    plugin.configure()

  File "/usr/local/lib/python2.7/dist-packages/yandextank/plugins/Phantom/plugin.py", line 72, in configure
    self.phantom_config = self.phantom.config_file

  File "/usr/local/lib/python2.7/dist-packages/yandextank/plugins/Phantom/plugin.py", line 81, in phantom
    self._phantom.read_config()

  File "/usr/local/lib/python2.7/dist-packages/yandextank/plugins/Phantom/utils.py", line 95, in read_config
    stream.read_config()

  File "/usr/local/lib/python2.7/dist-packages/yandextank/plugins/Phantom/utils.py", line 275, in read_config
    self.address, do_test_connect, explicit_port)

  File "/usr/local/lib/python2.7/dist-packages/yandextank/common/util.py", line 555, in resolve
    raise RuntimeError(msg % address_str)

2022-05-16 20:21:30,816 [INFO] root consoleworker.py:269	Trying to clean up
2022-05-16 20:21:30,818 [INFO] yandextank.core.tankcore tankcore.py:561	Releasing lock: /var/lock/lunapark_xbqW97.lock
2022-05-16 20:21:30,825 [WARNING] root consoleworker.py:408	Job number is not available yet
2022-05-16 20:21:30,832 [WARNING] root consoleworker.py:415	Job number is not available yet
2022-05-16 20:21:30,854 [DEBUG] yandextank.core.tankcore tankcore.py:367	Collecting artifacts
2022-05-16 20:21:30,856 [INFO] yandextank.core.tankcore tankcore.py:368	Artifacts dir: /var/loadtest/logs/2022-05-16_20-21-30.471649
2022-05-16 20:21:30,859 [DEBUG] yandextank.core.tankcore tankcore.py:422	Collecting file: /var/loadtest/logs/2022-05-16_20-21-30.471649/phout_piPd7l.log to /var/loadtest/logs/2022-05-16_20-21-30.471649/phout_piPd7l.log
2022-05-16 20:21:30,862 [WARNING] yandextank.core.tankcore tankcore.py:429	File already exists: /var/loadtest/logs/2022-05-16_20-21-30.471649/phout_piPd7l.log
2022-05-16 20:21:30,865 [DEBUG] yandextank.core.tankcore tankcore.py:422	Collecting file: /var/loadtest/logs/2022-05-16_20-21-30.471649/answ_vw2VFK.log to /var/loadtest/logs/2022-05-16_20-21-30.471649/answ_vw2VFK.log
2022-05-16 20:21:30,866 [WARNING] yandextank.core.tankcore tankcore.py:429	File already exists: /var/loadtest/logs/2022-05-16_20-21-30.471649/answ_vw2VFK.log
2022-05-16 20:21:30,868 [DEBUG] yandextank.core.tankcore tankcore.py:422	Collecting file: validation_error.yaml to /var/loadtest/logs/2022-05-16_20-21-30.471649/validation_error.yaml
2022-05-16 20:21:30,871 [WARNING] yandextank.core.tankcore tankcore.py:424	File not found to collect: validation_error.yaml
2022-05-16 20:21:30,874 [DEBUG] yandextank.core.tankcore tankcore.py:422	Collecting file: /var/loadtest/logs/2022-05-16_20-21-30.471649/phantom_stat_tfUPGY.log to /var/loadtest/logs/2022-05-16_20-21-30.471649/phantom_stat_tfUPGY.log
2022-05-16 20:21:30,876 [WARNING] yandextank.core.tankcore tankcore.py:429	File already exists: /var/loadtest/logs/2022-05-16_20-21-30.471649/phantom_stat_tfUPGY.log
2022-05-16 20:21:30,881 [DEBUG] yandextank.core.tankcore tankcore.py:422	Collecting file: /var/loadtest/logs/2022-05-16_20-21-30.471649/phantom_07W8th.log to /var/loadtest/logs/2022-05-16_20-21-30.471649/phantom_07W8th.log
2022-05-16 20:21:30,883 [WARNING] yandextank.core.tankcore tankcore.py:429	File already exists: /var/loadtest/logs/2022-05-16_20-21-30.471649/phantom_07W8th.log
