2022-05-16 20:19:33,017 [INFO] root consoleworker.py:434	Log file created
2022-05-16 20:19:33,018 [INFO] root consoleworker.py:438	Logging handler <logging.FileHandler object at 0x40192a2c10> added
2022-05-16 20:19:33,019 [INFO] root consoleworker.py:438	Logging handler <logging.StreamHandler object at 0x401926a850> added
2022-05-16 20:19:33,021 [INFO] root consoleworker.py:438	Logging handler <logging.StreamHandler object at 0x401928ea50> added
2022-05-16 20:19:33,022 [INFO] root consoleworker.py:373	Created a folder for the test. /var/loadtest/logs/2022-05-16_20-19-32.827611
2022-05-16 20:19:33,023 [INFO] yandextank.core.tankcore tankcore.py:237	Configuring plugins...
2022-05-16 20:19:33,025 [INFO] yandextank.core.tankcore tankcore.py:190	Loading plugins...
2022-05-16 20:19:33,027 [DEBUG] yandextank.core.tankcore tankcore.py:192	Loading plugin phantom from yandextank.plugins.Phantom
2022-05-16 20:19:33,030 [DEBUG] yandextank.core.tankcore tankcore.py:192	Loading plugin rcheck from yandextank.plugins.ResourceCheck
2022-05-16 20:19:33,034 [DEBUG] yandextank.core.tankcore tankcore.py:192	Loading plugin json_report from yandextank.plugins.JsonReport
2022-05-16 20:19:33,048 [DEBUG] yandextank.core.tankcore tankcore.py:192	Loading plugin overload from yandextank.plugins.DataUploader
2022-05-16 20:19:33,051 [DEBUG] yandextank.core.tankcore tankcore.py:192	Loading plugin rcassert from yandextank.plugins.RCAssert
2022-05-16 20:19:33,052 [DEBUG] yandextank.core.tankcore tankcore.py:192	Loading plugin console from yandextank.plugins.Console
2022-05-16 20:19:33,053 [DEBUG] yandextank.core.tankcore tankcore.py:192	Loading plugin shellexec from yandextank.plugins.ShellExec
2022-05-16 20:19:33,054 [DEBUG] yandextank.core.tankcore tankcore.py:192	Loading plugin autostop from yandextank.plugins.Autostop
2022-05-16 20:19:33,055 [DEBUG] yandextank.core.tankcore tankcore.py:212	Plugin instances: {'plugin_phantom': <yandextank.plugins.Phantom.plugin.Plugin object at 0x401959ff50>, 'plugin_autostop': <yandextank.plugins.Autostop.plugin.Plugin object at 0x40195b11d0>, 'plugin_shellexec': <yandextank.plugins.ShellExec.plugin.Plugin object at 0x40195b10d0>, 'plugin_console': <yandextank.plugins.Console.plugin.Plugin object at 0x40195b1550>, 'plugin_rcassert': <yandextank.plugins.RCAssert.plugin.Plugin object at 0x40195b1050>, 'plugin_rcheck': <yandextank.plugins.ResourceCheck.plugin.Plugin object at 0x401959fe50>, 'plugin_overload': <yandextank.plugins.DataUploader.plugin.Plugin object at 0x401959fb10>, 'plugin_json_report': <yandextank.plugins.JsonReport.plugin.Plugin object at 0x401920aa10>}
2022-05-16 20:19:33,056 [DEBUG] yandextank.core.tankcore tankcore.py:244	Configuring <yandextank.plugins.Phantom.plugin.Plugin object at 0x401959ff50>
2022-05-16 20:19:33,059 [DEBUG] yandextank.core.tankcore tankcore.py:391	Searching for plugin: <class 'yandextank.plugins.Autostop.plugin.Plugin'>
2022-05-16 20:19:33,074 [DEBUG] yandextank.core.tankcore tankcore.py:446	Adding artifact file to collect (keep=False): /var/loadtest/logs/2022-05-16_20-19-32.827611/answ_Rmzxao.log
2022-05-16 20:19:33,082 [DEBUG] yandextank.core.tankcore tankcore.py:446	Adding artifact file to collect (keep=False): /var/loadtest/logs/2022-05-16_20-19-32.827611/phout_zORM1M.log
2022-05-16 20:19:33,084 [DEBUG] yandextank.core.tankcore tankcore.py:446	Adding artifact file to collect (keep=False): /var/loadtest/logs/2022-05-16_20-19-32.827611/phantom_stat_8zdhkL.log
2022-05-16 20:19:33,088 [DEBUG] yandextank.core.tankcore tankcore.py:446	Adding artifact file to collect (keep=False): /var/loadtest/logs/2022-05-16_20-19-32.827611/phantom_9J0vrt.log
2022-05-16 20:19:33,090 [DEBUG] yandextank.common.util util.py:479	Trying to resolve address string: localhost:8080
2022-05-16 20:19:33,095 [DEBUG] yandextank.common.util util.py:516	Parsing port
2022-05-16 20:19:33,107 [DEBUG] yandextank.common.util util.py:527	Lookup result: [(2, 1, 6, '', ('127.0.0.1', 8080)), (2, 2, 17, '', ('127.0.0.1', 8080)), (2, 3, 0, '', ('127.0.0.1', 8080)), (10, 1, 6, '', ('::1', 8080, 0, 0)), (10, 2, 17, '', ('::1', 8080, 0, 0)), (10, 3, 0, '', ('::1', 8080, 0, 0))]
2022-05-16 20:19:33,109 [INFO] yandextank.common.util util.py:546	Testing connection to resolved address 127.0.0.1 and port 8080
2022-05-16 20:19:33,115 [DEBUG] yandextank.common.util util.py:565	Exception on connect attempt [127.0.0.1]:8080 : Traceback (most recent call last):
  File "/usr/local/lib/python2.7/dist-packages/yandextank/common/util.py", line 561, in __test
    test_sock.connect(sa)
  File "/usr/lib/python2.7/socket.py", line 228, in meth
    return getattr(self._sock,name)(*args)
error: [Errno 111] Connection refused

2022-05-16 20:19:33,117 [INFO] yandextank.common.util util.py:549	Failed TCP connection test using [127.0.0.1]:8080
2022-05-16 20:19:33,121 [DEBUG] yandextank.common.util util.py:550	Failed TCP connection test using [127.0.0.1]:8080
Traceback (most recent call last):
  File "/usr/local/lib/python2.7/dist-packages/yandextank/common/util.py", line 547, in resolve
    self.__test(family, (parsed_ip, port))
  File "/usr/local/lib/python2.7/dist-packages/yandextank/common/util.py", line 567, in __test
    raise RuntimeError(msg % (sa[0], sa[1]))
RuntimeError: TCP Connection test failed for [127.0.0.1]:8080, use phantom.connection_test=0 to disable it
2022-05-16 20:19:33,124 [INFO] yandextank.common.util util.py:546	Testing connection to resolved address 127.0.0.1 and port 8080
2022-05-16 20:19:33,127 [DEBUG] yandextank.common.util util.py:565	Exception on connect attempt [127.0.0.1]:8080 : Traceback (most recent call last):
  File "/usr/local/lib/python2.7/dist-packages/yandextank/common/util.py", line 561, in __test
    test_sock.connect(sa)
  File "/usr/lib/python2.7/socket.py", line 228, in meth
    return getattr(self._sock,name)(*args)
error: [Errno 111] Connection refused

2022-05-16 20:19:33,130 [INFO] yandextank.common.util util.py:549	Failed TCP connection test using [127.0.0.1]:8080
2022-05-16 20:19:33,134 [DEBUG] yandextank.common.util util.py:550	Failed TCP connection test using [127.0.0.1]:8080
Traceback (most recent call last):
  File "/usr/local/lib/python2.7/dist-packages/yandextank/common/util.py", line 547, in resolve
    self.__test(family, (parsed_ip, port))
  File "/usr/local/lib/python2.7/dist-packages/yandextank/common/util.py", line 567, in __test
    raise RuntimeError(msg % (sa[0], sa[1]))
RuntimeError: TCP Connection test failed for [127.0.0.1]:8080, use phantom.connection_test=0 to disable it
2022-05-16 20:19:33,137 [INFO] yandextank.common.util util.py:546	Testing connection to resolved address 127.0.0.1 and port 8080
2022-05-16 20:19:33,140 [DEBUG] yandextank.common.util util.py:565	Exception on connect attempt [127.0.0.1]:8080 : Traceback (most recent call last):
  File "/usr/local/lib/python2.7/dist-packages/yandextank/common/util.py", line 561, in __test
    test_sock.connect(sa)
  File "/usr/lib/python2.7/socket.py", line 228, in meth
    return getattr(self._sock,name)(*args)
error: [Errno 111] Connection refused

2022-05-16 20:19:33,142 [INFO] yandextank.common.util util.py:549	Failed TCP connection test using [127.0.0.1]:8080
2022-05-16 20:19:33,143 [DEBUG] yandextank.common.util util.py:550	Failed TCP connection test using [127.0.0.1]:8080
Traceback (most recent call last):
  File "/usr/local/lib/python2.7/dist-packages/yandextank/common/util.py", line 547, in resolve
    self.__test(family, (parsed_ip, port))
  File "/usr/local/lib/python2.7/dist-packages/yandextank/common/util.py", line 567, in __test
    raise RuntimeError(msg % (sa[0], sa[1]))
RuntimeError: TCP Connection test failed for [127.0.0.1]:8080, use phantom.connection_test=0 to disable it
2022-05-16 20:19:33,146 [INFO] yandextank.common.util util.py:546	Testing connection to resolved address ::1 and port 8080
2022-05-16 20:19:33,150 [DEBUG] yandextank.common.util util.py:565	Exception on connect attempt [::1]:8080 : Traceback (most recent call last):
  File "/usr/local/lib/python2.7/dist-packages/yandextank/common/util.py", line 561, in __test
    test_sock.connect(sa)
  File "/usr/lib/python2.7/socket.py", line 228, in meth
    return getattr(self._sock,name)(*args)
error: [Errno 99] Cannot assign requested address

2022-05-16 20:19:33,153 [INFO] yandextank.common.util util.py:549	Failed TCP connection test using [::1]:8080
2022-05-16 20:19:33,154 [DEBUG] yandextank.common.util util.py:550	Failed TCP connection test using [::1]:8080
Traceback (most recent call last):
  File "/usr/local/lib/python2.7/dist-packages/yandextank/common/util.py", line 547, in resolve
    self.__test(family, (parsed_ip, port))
  File "/usr/local/lib/python2.7/dist-packages/yandextank/common/util.py", line 567, in __test
    raise RuntimeError(msg % (sa[0], sa[1]))
RuntimeError: TCP Connection test failed for [::1]:8080, use phantom.connection_test=0 to disable it
2022-05-16 20:19:33,155 [INFO] yandextank.common.util util.py:546	Testing connection to resolved address ::1 and port 8080
2022-05-16 20:19:33,157 [DEBUG] yandextank.common.util util.py:565	Exception on connect attempt [::1]:8080 : Traceback (most recent call last):
  File "/usr/local/lib/python2.7/dist-packages/yandextank/common/util.py", line 561, in __test
    test_sock.connect(sa)
  File "/usr/lib/python2.7/socket.py", line 228, in meth
    return getattr(self._sock,name)(*args)
error: [Errno 99] Cannot assign requested address

2022-05-16 20:19:33,158 [INFO] yandextank.common.util util.py:549	Failed TCP connection test using [::1]:8080
2022-05-16 20:19:33,160 [DEBUG] yandextank.common.util util.py:550	Failed TCP connection test using [::1]:8080
Traceback (most recent call last):
  File "/usr/local/lib/python2.7/dist-packages/yandextank/common/util.py", line 547, in resolve
    self.__test(family, (parsed_ip, port))
  File "/usr/local/lib/python2.7/dist-packages/yandextank/common/util.py", line 567, in __test
    raise RuntimeError(msg % (sa[0], sa[1]))
RuntimeError: TCP Connection test failed for [::1]:8080, use phantom.connection_test=0 to disable it
2022-05-16 20:19:33,161 [INFO] yandextank.common.util util.py:546	Testing connection to resolved address ::1 and port 8080
2022-05-16 20:19:33,163 [DEBUG] yandextank.common.util util.py:565	Exception on connect attempt [::1]:8080 : Traceback (most recent call last):
  File "/usr/local/lib/python2.7/dist-packages/yandextank/common/util.py", line 561, in __test
    test_sock.connect(sa)
  File "/usr/lib/python2.7/socket.py", line 228, in meth
    return getattr(self._sock,name)(*args)
error: [Errno 99] Cannot assign requested address

2022-05-16 20:19:33,165 [INFO] yandextank.common.util util.py:549	Failed TCP connection test using [::1]:8080
2022-05-16 20:19:33,167 [DEBUG] yandextank.common.util util.py:550	Failed TCP connection test using [::1]:8080
Traceback (most recent call last):
  File "/usr/local/lib/python2.7/dist-packages/yandextank/common/util.py", line 547, in resolve
    self.__test(family, (parsed_ip, port))
  File "/usr/local/lib/python2.7/dist-packages/yandextank/common/util.py", line 567, in __test
    raise RuntimeError(msg % (sa[0], sa[1]))
RuntimeError: TCP Connection test failed for [::1]:8080, use phantom.connection_test=0 to disable it
2022-05-16 20:19:33,172 [ERROR] root consoleworker.py:268	Exception occurred:
<type 'exceptions.RuntimeError'>: All connection attempts failed for localhost, use {phantom.connection_test: false} to disable it
  File "/usr/local/lib/python2.7/dist-packages/yandextank/core/consoleworker.py", line 375, in run
    self.core.plugins_configure()

  File "/usr/local/lib/python2.7/dist-packages/yandextank/core/tankcore.py", line 245, in plugins_configure
    plugin.configure()

  File "/usr/local/lib/python2.7/dist-packages/yandextank/plugins/Phantom/plugin.py", line 72, in configure
    self.phantom_config = self.phantom.config_file

  File "/usr/local/lib/python2.7/dist-packages/yandextank/plugins/Phantom/plugin.py", line 81, in phantom
    self._phantom.read_config()

  File "/usr/local/lib/python2.7/dist-packages/yandextank/plugins/Phantom/utils.py", line 95, in read_config
    stream.read_config()

  File "/usr/local/lib/python2.7/dist-packages/yandextank/plugins/Phantom/utils.py", line 275, in read_config
    self.address, do_test_connect, explicit_port)

  File "/usr/local/lib/python2.7/dist-packages/yandextank/common/util.py", line 555, in resolve
    raise RuntimeError(msg % address_str)

2022-05-16 20:19:33,175 [INFO] root consoleworker.py:269	Trying to clean up
2022-05-16 20:19:33,176 [INFO] yandextank.core.tankcore tankcore.py:561	Releasing lock: /var/lock/lunapark_QHo8P7.lock
2022-05-16 20:19:33,183 [WARNING] root consoleworker.py:408	Job number is not available yet
2022-05-16 20:19:33,186 [WARNING] root consoleworker.py:415	Job number is not available yet
2022-05-16 20:19:33,204 [DEBUG] yandextank.core.tankcore tankcore.py:367	Collecting artifacts
2022-05-16 20:19:33,205 [INFO] yandextank.core.tankcore tankcore.py:368	Artifacts dir: /var/loadtest/logs/2022-05-16_20-19-32.827611
2022-05-16 20:19:33,206 [DEBUG] yandextank.core.tankcore tankcore.py:422	Collecting file: /var/loadtest/logs/2022-05-16_20-19-32.827611/phantom_stat_8zdhkL.log to /var/loadtest/logs/2022-05-16_20-19-32.827611/phantom_stat_8zdhkL.log
2022-05-16 20:19:33,208 [WARNING] yandextank.core.tankcore tankcore.py:429	File already exists: /var/loadtest/logs/2022-05-16_20-19-32.827611/phantom_stat_8zdhkL.log
2022-05-16 20:19:33,210 [DEBUG] yandextank.core.tankcore tankcore.py:422	Collecting file: /var/loadtest/logs/2022-05-16_20-19-32.827611/answ_Rmzxao.log to /var/loadtest/logs/2022-05-16_20-19-32.827611/answ_Rmzxao.log
2022-05-16 20:19:33,213 [WARNING] yandextank.core.tankcore tankcore.py:429	File already exists: /var/loadtest/logs/2022-05-16_20-19-32.827611/answ_Rmzxao.log
2022-05-16 20:19:33,218 [DEBUG] yandextank.core.tankcore tankcore.py:422	Collecting file: /var/loadtest/logs/2022-05-16_20-19-32.827611/phantom_9J0vrt.log to /var/loadtest/logs/2022-05-16_20-19-32.827611/phantom_9J0vrt.log
2022-05-16 20:19:33,221 [WARNING] yandextank.core.tankcore tankcore.py:429	File already exists: /var/loadtest/logs/2022-05-16_20-19-32.827611/phantom_9J0vrt.log
2022-05-16 20:19:33,226 [DEBUG] yandextank.core.tankcore tankcore.py:422	Collecting file: validation_error.yaml to /var/loadtest/logs/2022-05-16_20-19-32.827611/validation_error.yaml
2022-05-16 20:19:33,232 [WARNING] yandextank.core.tankcore tankcore.py:424	File not found to collect: validation_error.yaml
2022-05-16 20:19:33,240 [DEBUG] yandextank.core.tankcore tankcore.py:422	Collecting file: /var/loadtest/logs/2022-05-16_20-19-32.827611/phout_zORM1M.log to /var/loadtest/logs/2022-05-16_20-19-32.827611/phout_zORM1M.log
2022-05-16 20:19:33,242 [WARNING] yandextank.core.tankcore tankcore.py:429	File already exists: /var/loadtest/logs/2022-05-16_20-19-32.827611/phout_zORM1M.log
