2022-05-16 20:23:22,742 [INFO] root consoleworker.py:434	Log file created
2022-05-16 20:23:22,744 [INFO] root consoleworker.py:438	Logging handler <logging.FileHandler object at 0x40192a2c10> added
2022-05-16 20:23:22,746 [INFO] root consoleworker.py:438	Logging handler <logging.StreamHandler object at 0x401926a850> added
2022-05-16 20:23:22,747 [INFO] root consoleworker.py:438	Logging handler <logging.StreamHandler object at 0x401928ea50> added
2022-05-16 20:23:22,748 [INFO] root consoleworker.py:373	Created a folder for the test. /var/loadtest/logs/2022-05-16_20-23-22.563408
2022-05-16 20:23:22,750 [INFO] yandextank.core.tankcore tankcore.py:237	Configuring plugins...
2022-05-16 20:23:22,752 [INFO] yandextank.core.tankcore tankcore.py:190	Loading plugins...
2022-05-16 20:23:22,753 [DEBUG] yandextank.core.tankcore tankcore.py:192	Loading plugin phantom from yandextank.plugins.Phantom
2022-05-16 20:23:22,754 [DEBUG] yandextank.core.tankcore tankcore.py:192	Loading plugin rcheck from yandextank.plugins.ResourceCheck
2022-05-16 20:23:22,755 [DEBUG] yandextank.core.tankcore tankcore.py:192	Loading plugin json_report from yandextank.plugins.JsonReport
2022-05-16 20:23:22,765 [DEBUG] yandextank.core.tankcore tankcore.py:192	Loading plugin overload from yandextank.plugins.DataUploader
2022-05-16 20:23:22,767 [DEBUG] yandextank.core.tankcore tankcore.py:192	Loading plugin rcassert from yandextank.plugins.RCAssert
2022-05-16 20:23:22,768 [DEBUG] yandextank.core.tankcore tankcore.py:192	Loading plugin console from yandextank.plugins.Console
2022-05-16 20:23:22,769 [DEBUG] yandextank.core.tankcore tankcore.py:192	Loading plugin shellexec from yandextank.plugins.ShellExec
2022-05-16 20:23:22,770 [DEBUG] yandextank.core.tankcore tankcore.py:192	Loading plugin autostop from yandextank.plugins.Autostop
2022-05-16 20:23:22,771 [DEBUG] yandextank.core.tankcore tankcore.py:212	Plugin instances: {'plugin_phantom': <yandextank.plugins.Phantom.plugin.Plugin object at 0x401959ff50>, 'plugin_autostop': <yandextank.plugins.Autostop.plugin.Plugin object at 0x40195b11d0>, 'plugin_shellexec': <yandextank.plugins.ShellExec.plugin.Plugin object at 0x40195b10d0>, 'plugin_console': <yandextank.plugins.Console.plugin.Plugin object at 0x40195b1550>, 'plugin_rcassert': <yandextank.plugins.RCAssert.plugin.Plugin object at 0x40195b1050>, 'plugin_rcheck': <yandextank.plugins.ResourceCheck.plugin.Plugin object at 0x401959fe50>, 'plugin_overload': <yandextank.plugins.DataUploader.plugin.Plugin object at 0x401959fb10>, 'plugin_json_report': <yandextank.plugins.JsonReport.plugin.Plugin object at 0x401920aa10>}
2022-05-16 20:23:22,772 [DEBUG] yandextank.core.tankcore tankcore.py:244	Configuring <yandextank.plugins.Phantom.plugin.Plugin object at 0x401959ff50>
2022-05-16 20:23:22,774 [DEBUG] yandextank.core.tankcore tankcore.py:391	Searching for plugin: <class 'yandextank.plugins.Autostop.plugin.Plugin'>
2022-05-16 20:23:22,786 [DEBUG] yandextank.core.tankcore tankcore.py:446	Adding artifact file to collect (keep=False): /var/loadtest/logs/2022-05-16_20-23-22.563408/answ_uHwkrU.log
2022-05-16 20:23:22,793 [DEBUG] yandextank.core.tankcore tankcore.py:446	Adding artifact file to collect (keep=False): /var/loadtest/logs/2022-05-16_20-23-22.563408/phout_qAEoOL.log
2022-05-16 20:23:22,795 [DEBUG] yandextank.core.tankcore tankcore.py:446	Adding artifact file to collect (keep=False): /var/loadtest/logs/2022-05-16_20-23-22.563408/phantom_stat_q7Wbfj.log
2022-05-16 20:23:22,800 [DEBUG] yandextank.core.tankcore tankcore.py:446	Adding artifact file to collect (keep=False): /var/loadtest/logs/2022-05-16_20-23-22.563408/phantom_ttWUjK.log
2022-05-16 20:23:22,801 [DEBUG] yandextank.common.util util.py:479	Trying to resolve address string: localhost:8080
2022-05-16 20:23:22,806 [DEBUG] yandextank.common.util util.py:516	Parsing port
2022-05-16 20:23:22,813 [DEBUG] yandextank.common.util util.py:527	Lookup result: [(2, 1, 6, '', ('127.0.0.1', 8080)), (2, 2, 17, '', ('127.0.0.1', 8080)), (2, 3, 0, '', ('127.0.0.1', 8080)), (10, 1, 6, '', ('::1', 8080, 0, 0)), (10, 2, 17, '', ('::1', 8080, 0, 0)), (10, 3, 0, '', ('::1', 8080, 0, 0))]
2022-05-16 20:23:22,815 [INFO] yandextank.common.util util.py:546	Testing connection to resolved address 127.0.0.1 and port 8080
2022-05-16 20:23:22,819 [DEBUG] yandextank.common.util util.py:565	Exception on connect attempt [127.0.0.1]:8080 : Traceback (most recent call last):
  File "/usr/local/lib/python2.7/dist-packages/yandextank/common/util.py", line 561, in __test
    test_sock.connect(sa)
  File "/usr/lib/python2.7/socket.py", line 228, in meth
    return getattr(self._sock,name)(*args)
error: [Errno 111] Connection refused

2022-05-16 20:23:22,820 [INFO] yandextank.common.util util.py:549	Failed TCP connection test using [127.0.0.1]:8080
2022-05-16 20:23:22,821 [DEBUG] yandextank.common.util util.py:550	Failed TCP connection test using [127.0.0.1]:8080
Traceback (most recent call last):
  File "/usr/local/lib/python2.7/dist-packages/yandextank/common/util.py", line 547, in resolve
    self.__test(family, (parsed_ip, port))
  File "/usr/local/lib/python2.7/dist-packages/yandextank/common/util.py", line 567, in __test
    raise RuntimeError(msg % (sa[0], sa[1]))
RuntimeError: TCP Connection test failed for [127.0.0.1]:8080, use phantom.connection_test=0 to disable it
2022-05-16 20:23:22,822 [INFO] yandextank.common.util util.py:546	Testing connection to resolved address 127.0.0.1 and port 8080
2022-05-16 20:23:22,824 [DEBUG] yandextank.common.util util.py:565	Exception on connect attempt [127.0.0.1]:8080 : Traceback (most recent call last):
  File "/usr/local/lib/python2.7/dist-packages/yandextank/common/util.py", line 561, in __test
    test_sock.connect(sa)
  File "/usr/lib/python2.7/socket.py", line 228, in meth
    return getattr(self._sock,name)(*args)
error: [Errno 111] Connection refused

2022-05-16 20:23:22,826 [INFO] yandextank.common.util util.py:549	Failed TCP connection test using [127.0.0.1]:8080
2022-05-16 20:23:22,828 [DEBUG] yandextank.common.util util.py:550	Failed TCP connection test using [127.0.0.1]:8080
Traceback (most recent call last):
  File "/usr/local/lib/python2.7/dist-packages/yandextank/common/util.py", line 547, in resolve
    self.__test(family, (parsed_ip, port))
  File "/usr/local/lib/python2.7/dist-packages/yandextank/common/util.py", line 567, in __test
    raise RuntimeError(msg % (sa[0], sa[1]))
RuntimeError: TCP Connection test failed for [127.0.0.1]:8080, use phantom.connection_test=0 to disable it
2022-05-16 20:23:22,830 [INFO] yandextank.common.util util.py:546	Testing connection to resolved address 127.0.0.1 and port 8080
2022-05-16 20:23:22,833 [DEBUG] yandextank.common.util util.py:565	Exception on connect attempt [127.0.0.1]:8080 : Traceback (most recent call last):
  File "/usr/local/lib/python2.7/dist-packages/yandextank/common/util.py", line 561, in __test
    test_sock.connect(sa)
  File "/usr/lib/python2.7/socket.py", line 228, in meth
    return getattr(self._sock,name)(*args)
error: [Errno 111] Connection refused

2022-05-16 20:23:22,835 [INFO] yandextank.common.util util.py:549	Failed TCP connection test using [127.0.0.1]:8080
2022-05-16 20:23:22,836 [DEBUG] yandextank.common.util util.py:550	Failed TCP connection test using [127.0.0.1]:8080
Traceback (most recent call last):
  File "/usr/local/lib/python2.7/dist-packages/yandextank/common/util.py", line 547, in resolve
    self.__test(family, (parsed_ip, port))
  File "/usr/local/lib/python2.7/dist-packages/yandextank/common/util.py", line 567, in __test
    raise RuntimeError(msg % (sa[0], sa[1]))
RuntimeError: TCP Connection test failed for [127.0.0.1]:8080, use phantom.connection_test=0 to disable it
2022-05-16 20:23:22,837 [INFO] yandextank.common.util util.py:546	Testing connection to resolved address ::1 and port 8080
2022-05-16 20:23:22,841 [DEBUG] yandextank.common.util util.py:565	Exception on connect attempt [::1]:8080 : Traceback (most recent call last):
  File "/usr/local/lib/python2.7/dist-packages/yandextank/common/util.py", line 561, in __test
    test_sock.connect(sa)
  File "/usr/lib/python2.7/socket.py", line 228, in meth
    return getattr(self._sock,name)(*args)
error: [Errno 99] Cannot assign requested address

2022-05-16 20:23:22,844 [INFO] yandextank.common.util util.py:549	Failed TCP connection test using [::1]:8080
2022-05-16 20:23:22,847 [DEBUG] yandextank.common.util util.py:550	Failed TCP connection test using [::1]:8080
Traceback (most recent call last):
  File "/usr/local/lib/python2.7/dist-packages/yandextank/common/util.py", line 547, in resolve
    self.__test(family, (parsed_ip, port))
  File "/usr/local/lib/python2.7/dist-packages/yandextank/common/util.py", line 567, in __test
    raise RuntimeError(msg % (sa[0], sa[1]))
RuntimeError: TCP Connection test failed for [::1]:8080, use phantom.connection_test=0 to disable it
2022-05-16 20:23:22,851 [INFO] yandextank.common.util util.py:546	Testing connection to resolved address ::1 and port 8080
2022-05-16 20:23:22,853 [DEBUG] yandextank.common.util util.py:565	Exception on connect attempt [::1]:8080 : Traceback (most recent call last):
  File "/usr/local/lib/python2.7/dist-packages/yandextank/common/util.py", line 561, in __test
    test_sock.connect(sa)
  File "/usr/lib/python2.7/socket.py", line 228, in meth
    return getattr(self._sock,name)(*args)
error: [Errno 99] Cannot assign requested address

2022-05-16 20:23:22,856 [INFO] yandextank.common.util util.py:549	Failed TCP connection test using [::1]:8080
2022-05-16 20:23:22,857 [DEBUG] yandextank.common.util util.py:550	Failed TCP connection test using [::1]:8080
Traceback (most recent call last):
  File "/usr/local/lib/python2.7/dist-packages/yandextank/common/util.py", line 547, in resolve
    self.__test(family, (parsed_ip, port))
  File "/usr/local/lib/python2.7/dist-packages/yandextank/common/util.py", line 567, in __test
    raise RuntimeError(msg % (sa[0], sa[1]))
RuntimeError: TCP Connection test failed for [::1]:8080, use phantom.connection_test=0 to disable it
2022-05-16 20:23:22,861 [INFO] yandextank.common.util util.py:546	Testing connection to resolved address ::1 and port 8080
2022-05-16 20:23:22,865 [DEBUG] yandextank.common.util util.py:565	Exception on connect attempt [::1]:8080 : Traceback (most recent call last):
  File "/usr/local/lib/python2.7/dist-packages/yandextank/common/util.py", line 561, in __test
    test_sock.connect(sa)
  File "/usr/lib/python2.7/socket.py", line 228, in meth
    return getattr(self._sock,name)(*args)
error: [Errno 99] Cannot assign requested address

2022-05-16 20:23:22,867 [INFO] yandextank.common.util util.py:549	Failed TCP connection test using [::1]:8080
2022-05-16 20:23:22,869 [DEBUG] yandextank.common.util util.py:550	Failed TCP connection test using [::1]:8080
Traceback (most recent call last):
  File "/usr/local/lib/python2.7/dist-packages/yandextank/common/util.py", line 547, in resolve
    self.__test(family, (parsed_ip, port))
  File "/usr/local/lib/python2.7/dist-packages/yandextank/common/util.py", line 567, in __test
    raise RuntimeError(msg % (sa[0], sa[1]))
RuntimeError: TCP Connection test failed for [::1]:8080, use phantom.connection_test=0 to disable it
2022-05-16 20:23:22,873 [ERROR] root consoleworker.py:268	Exception occurred:
<type 'exceptions.RuntimeError'>: All connection attempts failed for localhost, use {phantom.connection_test: false} to disable it
  File "/usr/local/lib/python2.7/dist-packages/yandextank/core/consoleworker.py", line 375, in run
    self.core.plugins_configure()

  File "/usr/local/lib/python2.7/dist-packages/yandextank/core/tankcore.py", line 245, in plugins_configure
    plugin.configure()

  File "/usr/local/lib/python2.7/dist-packages/yandextank/plugins/Phantom/plugin.py", line 72, in configure
    self.phantom_config = self.phantom.config_file

  File "/usr/local/lib/python2.7/dist-packages/yandextank/plugins/Phantom/plugin.py", line 81, in phantom
    self._phantom.read_config()

  File "/usr/local/lib/python2.7/dist-packages/yandextank/plugins/Phantom/utils.py", line 95, in read_config
    stream.read_config()

  File "/usr/local/lib/python2.7/dist-packages/yandextank/plugins/Phantom/utils.py", line 275, in read_config
    self.address, do_test_connect, explicit_port)

  File "/usr/local/lib/python2.7/dist-packages/yandextank/common/util.py", line 555, in resolve
    raise RuntimeError(msg % address_str)

2022-05-16 20:23:22,881 [INFO] root consoleworker.py:269	Trying to clean up
2022-05-16 20:23:22,886 [INFO] yandextank.core.tankcore tankcore.py:561	Releasing lock: /var/lock/lunapark_pZmf1B.lock
2022-05-16 20:23:22,895 [WARNING] root consoleworker.py:408	Job number is not available yet
2022-05-16 20:23:22,899 [WARNING] root consoleworker.py:415	Job number is not available yet
2022-05-16 20:23:22,917 [DEBUG] yandextank.core.tankcore tankcore.py:367	Collecting artifacts
2022-05-16 20:23:22,918 [INFO] yandextank.core.tankcore tankcore.py:368	Artifacts dir: /var/loadtest/logs/2022-05-16_20-23-22.563408
2022-05-16 20:23:22,920 [DEBUG] yandextank.core.tankcore tankcore.py:422	Collecting file: /var/loadtest/logs/2022-05-16_20-23-22.563408/answ_uHwkrU.log to /var/loadtest/logs/2022-05-16_20-23-22.563408/answ_uHwkrU.log
2022-05-16 20:23:22,922 [WARNING] yandextank.core.tankcore tankcore.py:429	File already exists: /var/loadtest/logs/2022-05-16_20-23-22.563408/answ_uHwkrU.log
2022-05-16 20:23:22,926 [DEBUG] yandextank.core.tankcore tankcore.py:422	Collecting file: /var/loadtest/logs/2022-05-16_20-23-22.563408/phantom_stat_q7Wbfj.log to /var/loadtest/logs/2022-05-16_20-23-22.563408/phantom_stat_q7Wbfj.log
2022-05-16 20:23:22,929 [WARNING] yandextank.core.tankcore tankcore.py:429	File already exists: /var/loadtest/logs/2022-05-16_20-23-22.563408/phantom_stat_q7Wbfj.log
2022-05-16 20:23:22,933 [DEBUG] yandextank.core.tankcore tankcore.py:422	Collecting file: validation_error.yaml to /var/loadtest/logs/2022-05-16_20-23-22.563408/validation_error.yaml
2022-05-16 20:23:22,936 [WARNING] yandextank.core.tankcore tankcore.py:424	File not found to collect: validation_error.yaml
2022-05-16 20:23:22,938 [DEBUG] yandextank.core.tankcore tankcore.py:422	Collecting file: /var/loadtest/logs/2022-05-16_20-23-22.563408/phout_qAEoOL.log to /var/loadtest/logs/2022-05-16_20-23-22.563408/phout_qAEoOL.log
2022-05-16 20:23:22,940 [WARNING] yandextank.core.tankcore tankcore.py:429	File already exists: /var/loadtest/logs/2022-05-16_20-23-22.563408/phout_qAEoOL.log
2022-05-16 20:23:22,945 [DEBUG] yandextank.core.tankcore tankcore.py:422	Collecting file: /var/loadtest/logs/2022-05-16_20-23-22.563408/phantom_ttWUjK.log to /var/loadtest/logs/2022-05-16_20-23-22.563408/phantom_ttWUjK.log
2022-05-16 20:23:22,948 [WARNING] yandextank.core.tankcore tankcore.py:429	File already exists: /var/loadtest/logs/2022-05-16_20-23-22.563408/phantom_ttWUjK.log
