2022-05-16 20:20:56,361 [INFO] root consoleworker.py:434	Log file created
2022-05-16 20:20:56,363 [INFO] root consoleworker.py:438	Logging handler <logging.FileHandler object at 0x40192a2c10> added
2022-05-16 20:20:56,364 [INFO] root consoleworker.py:438	Logging handler <logging.StreamHandler object at 0x401926a850> added
2022-05-16 20:20:56,365 [INFO] root consoleworker.py:438	Logging handler <logging.StreamHandler object at 0x401928ea50> added
2022-05-16 20:20:56,366 [INFO] root consoleworker.py:373	Created a folder for the test. /var/loadtest/logs/2022-05-16_20-20-56.176872
2022-05-16 20:20:56,368 [INFO] yandextank.core.tankcore tankcore.py:237	Configuring plugins...
2022-05-16 20:20:56,369 [INFO] yandextank.core.tankcore tankcore.py:190	Loading plugins...
2022-05-16 20:20:56,371 [DEBUG] yandextank.core.tankcore tankcore.py:192	Loading plugin phantom from yandextank.plugins.Phantom
2022-05-16 20:20:56,373 [DEBUG] yandextank.core.tankcore tankcore.py:192	Loading plugin rcheck from yandextank.plugins.ResourceCheck
2022-05-16 20:20:56,375 [DEBUG] yandextank.core.tankcore tankcore.py:192	Loading plugin json_report from yandextank.plugins.JsonReport
2022-05-16 20:20:56,384 [DEBUG] yandextank.core.tankcore tankcore.py:192	Loading plugin overload from yandextank.plugins.DataUploader
2022-05-16 20:20:56,385 [DEBUG] yandextank.core.tankcore tankcore.py:192	Loading plugin rcassert from yandextank.plugins.RCAssert
2022-05-16 20:20:56,386 [DEBUG] yandextank.core.tankcore tankcore.py:192	Loading plugin console from yandextank.plugins.Console
2022-05-16 20:20:56,387 [DEBUG] yandextank.core.tankcore tankcore.py:192	Loading plugin shellexec from yandextank.plugins.ShellExec
2022-05-16 20:20:56,388 [DEBUG] yandextank.core.tankcore tankcore.py:192	Loading plugin autostop from yandextank.plugins.Autostop
2022-05-16 20:20:56,389 [DEBUG] yandextank.core.tankcore tankcore.py:212	Plugin instances: {'plugin_phantom': <yandextank.plugins.Phantom.plugin.Plugin object at 0x401959ff50>, 'plugin_autostop': <yandextank.plugins.Autostop.plugin.Plugin object at 0x40195b11d0>, 'plugin_shellexec': <yandextank.plugins.ShellExec.plugin.Plugin object at 0x40195b10d0>, 'plugin_console': <yandextank.plugins.Console.plugin.Plugin object at 0x40195b1550>, 'plugin_rcassert': <yandextank.plugins.RCAssert.plugin.Plugin object at 0x40195b1050>, 'plugin_rcheck': <yandextank.plugins.ResourceCheck.plugin.Plugin object at 0x401959fe50>, 'plugin_overload': <yandextank.plugins.DataUploader.plugin.Plugin object at 0x401959fb10>, 'plugin_json_report': <yandextank.plugins.JsonReport.plugin.Plugin object at 0x401920aa10>}
2022-05-16 20:20:56,390 [DEBUG] yandextank.core.tankcore tankcore.py:244	Configuring <yandextank.plugins.Phantom.plugin.Plugin object at 0x401959ff50>
2022-05-16 20:20:56,393 [DEBUG] yandextank.core.tankcore tankcore.py:391	Searching for plugin: <class 'yandextank.plugins.Autostop.plugin.Plugin'>
2022-05-16 20:20:56,410 [DEBUG] yandextank.core.tankcore tankcore.py:446	Adding artifact file to collect (keep=False): /var/loadtest/logs/2022-05-16_20-20-56.176872/answ_jS3bJ9.log
2022-05-16 20:20:56,415 [DEBUG] yandextank.core.tankcore tankcore.py:446	Adding artifact file to collect (keep=False): /var/loadtest/logs/2022-05-16_20-20-56.176872/phout_zIRtLc.log
2022-05-16 20:20:56,416 [DEBUG] yandextank.core.tankcore tankcore.py:446	Adding artifact file to collect (keep=False): /var/loadtest/logs/2022-05-16_20-20-56.176872/phantom_stat_I2tMAQ.log
2022-05-16 20:20:56,422 [DEBUG] yandextank.core.tankcore tankcore.py:446	Adding artifact file to collect (keep=False): /var/loadtest/logs/2022-05-16_20-20-56.176872/phantom_WyEaFD.log
2022-05-16 20:20:56,424 [DEBUG] yandextank.common.util util.py:479	Trying to resolve address string: localhost:8080
2022-05-16 20:20:56,429 [DEBUG] yandextank.common.util util.py:516	Parsing port
2022-05-16 20:20:56,436 [DEBUG] yandextank.common.util util.py:527	Lookup result: [(2, 1, 6, '', ('127.0.0.1', 8080)), (2, 2, 17, '', ('127.0.0.1', 8080)), (2, 3, 0, '', ('127.0.0.1', 8080)), (10, 1, 6, '', ('::1', 8080, 0, 0)), (10, 2, 17, '', ('::1', 8080, 0, 0)), (10, 3, 0, '', ('::1', 8080, 0, 0))]
2022-05-16 20:20:56,438 [INFO] yandextank.common.util util.py:546	Testing connection to resolved address 127.0.0.1 and port 8080
2022-05-16 20:20:56,443 [DEBUG] yandextank.common.util util.py:565	Exception on connect attempt [127.0.0.1]:8080 : Traceback (most recent call last):
  File "/usr/local/lib/python2.7/dist-packages/yandextank/common/util.py", line 561, in __test
    test_sock.connect(sa)
  File "/usr/lib/python2.7/socket.py", line 228, in meth
    return getattr(self._sock,name)(*args)
error: [Errno 111] Connection refused

2022-05-16 20:20:56,444 [INFO] yandextank.common.util util.py:549	Failed TCP connection test using [127.0.0.1]:8080
2022-05-16 20:20:56,445 [DEBUG] yandextank.common.util util.py:550	Failed TCP connection test using [127.0.0.1]:8080
Traceback (most recent call last):
  File "/usr/local/lib/python2.7/dist-packages/yandextank/common/util.py", line 547, in resolve
    self.__test(family, (parsed_ip, port))
  File "/usr/local/lib/python2.7/dist-packages/yandextank/common/util.py", line 567, in __test
    raise RuntimeError(msg % (sa[0], sa[1]))
RuntimeError: TCP Connection test failed for [127.0.0.1]:8080, use phantom.connection_test=0 to disable it
2022-05-16 20:20:56,447 [INFO] yandextank.common.util util.py:546	Testing connection to resolved address 127.0.0.1 and port 8080
2022-05-16 20:20:56,450 [DEBUG] yandextank.common.util util.py:565	Exception on connect attempt [127.0.0.1]:8080 : Traceback (most recent call last):
  File "/usr/local/lib/python2.7/dist-packages/yandextank/common/util.py", line 561, in __test
    test_sock.connect(sa)
  File "/usr/lib/python2.7/socket.py", line 228, in meth
    return getattr(self._sock,name)(*args)
error: [Errno 111] Connection refused

2022-05-16 20:20:56,452 [INFO] yandextank.common.util util.py:549	Failed TCP connection test using [127.0.0.1]:8080
2022-05-16 20:20:56,453 [DEBUG] yandextank.common.util util.py:550	Failed TCP connection test using [127.0.0.1]:8080
Traceback (most recent call last):
  File "/usr/local/lib/python2.7/dist-packages/yandextank/common/util.py", line 547, in resolve
    self.__test(family, (parsed_ip, port))
  File "/usr/local/lib/python2.7/dist-packages/yandextank/common/util.py", line 567, in __test
    raise RuntimeError(msg % (sa[0], sa[1]))
RuntimeError: TCP Connection test failed for [127.0.0.1]:8080, use phantom.connection_test=0 to disable it
2022-05-16 20:20:56,454 [INFO] yandextank.common.util util.py:546	Testing connection to resolved address 127.0.0.1 and port 8080
2022-05-16 20:20:56,455 [DEBUG] yandextank.common.util util.py:565	Exception on connect attempt [127.0.0.1]:8080 : Traceback (most recent call last):
  File "/usr/local/lib/python2.7/dist-packages/yandextank/common/util.py", line 561, in __test
    test_sock.connect(sa)
  File "/usr/lib/python2.7/socket.py", line 228, in meth
    return getattr(self._sock,name)(*args)
error: [Errno 111] Connection refused

2022-05-16 20:20:56,456 [INFO] yandextank.common.util util.py:549	Failed TCP connection test using [127.0.0.1]:8080
2022-05-16 20:20:56,458 [DEBUG] yandextank.common.util util.py:550	Failed TCP connection test using [127.0.0.1]:8080
Traceback (most recent call last):
  File "/usr/local/lib/python2.7/dist-packages/yandextank/common/util.py", line 547, in resolve
    self.__test(family, (parsed_ip, port))
  File "/usr/local/lib/python2.7/dist-packages/yandextank/common/util.py", line 567, in __test
    raise RuntimeError(msg % (sa[0], sa[1]))
RuntimeError: TCP Connection test failed for [127.0.0.1]:8080, use phantom.connection_test=0 to disable it
2022-05-16 20:20:56,461 [INFO] yandextank.common.util util.py:546	Testing connection to resolved address ::1 and port 8080
2022-05-16 20:20:56,463 [DEBUG] yandextank.common.util util.py:565	Exception on connect attempt [::1]:8080 : Traceback (most recent call last):
  File "/usr/local/lib/python2.7/dist-packages/yandextank/common/util.py", line 561, in __test
    test_sock.connect(sa)
  File "/usr/lib/python2.7/socket.py", line 228, in meth
    return getattr(self._sock,name)(*args)
error: [Errno 99] Cannot assign requested address

2022-05-16 20:20:56,465 [INFO] yandextank.common.util util.py:549	Failed TCP connection test using [::1]:8080
2022-05-16 20:20:56,466 [DEBUG] yandextank.common.util util.py:550	Failed TCP connection test using [::1]:8080
Traceback (most recent call last):
  File "/usr/local/lib/python2.7/dist-packages/yandextank/common/util.py", line 547, in resolve
    self.__test(family, (parsed_ip, port))
  File "/usr/local/lib/python2.7/dist-packages/yandextank/common/util.py", line 567, in __test
    raise RuntimeError(msg % (sa[0], sa[1]))
RuntimeError: TCP Connection test failed for [::1]:8080, use phantom.connection_test=0 to disable it
2022-05-16 20:20:56,467 [INFO] yandextank.common.util util.py:546	Testing connection to resolved address ::1 and port 8080
2022-05-16 20:20:56,469 [DEBUG] yandextank.common.util util.py:565	Exception on connect attempt [::1]:8080 : Traceback (most recent call last):
  File "/usr/local/lib/python2.7/dist-packages/yandextank/common/util.py", line 561, in __test
    test_sock.connect(sa)
  File "/usr/lib/python2.7/socket.py", line 228, in meth
    return getattr(self._sock,name)(*args)
error: [Errno 99] Cannot assign requested address

2022-05-16 20:20:56,470 [INFO] yandextank.common.util util.py:549	Failed TCP connection test using [::1]:8080
2022-05-16 20:20:56,471 [DEBUG] yandextank.common.util util.py:550	Failed TCP connection test using [::1]:8080
Traceback (most recent call last):
  File "/usr/local/lib/python2.7/dist-packages/yandextank/common/util.py", line 547, in resolve
    self.__test(family, (parsed_ip, port))
  File "/usr/local/lib/python2.7/dist-packages/yandextank/common/util.py", line 567, in __test
    raise RuntimeError(msg % (sa[0], sa[1]))
RuntimeError: TCP Connection test failed for [::1]:8080, use phantom.connection_test=0 to disable it
2022-05-16 20:20:56,473 [INFO] yandextank.common.util util.py:546	Testing connection to resolved address ::1 and port 8080
2022-05-16 20:20:56,475 [DEBUG] yandextank.common.util util.py:565	Exception on connect attempt [::1]:8080 : Traceback (most recent call last):
  File "/usr/local/lib/python2.7/dist-packages/yandextank/common/util.py", line 561, in __test
    test_sock.connect(sa)
  File "/usr/lib/python2.7/socket.py", line 228, in meth
    return getattr(self._sock,name)(*args)
error: [Errno 99] Cannot assign requested address

2022-05-16 20:20:56,477 [INFO] yandextank.common.util util.py:549	Failed TCP connection test using [::1]:8080
2022-05-16 20:20:56,479 [DEBUG] yandextank.common.util util.py:550	Failed TCP connection test using [::1]:8080
Traceback (most recent call last):
  File "/usr/local/lib/python2.7/dist-packages/yandextank/common/util.py", line 547, in resolve
    self.__test(family, (parsed_ip, port))
  File "/usr/local/lib/python2.7/dist-packages/yandextank/common/util.py", line 567, in __test
    raise RuntimeError(msg % (sa[0], sa[1]))
RuntimeError: TCP Connection test failed for [::1]:8080, use phantom.connection_test=0 to disable it
2022-05-16 20:20:56,482 [ERROR] root consoleworker.py:268	Exception occurred:
<type 'exceptions.RuntimeError'>: All connection attempts failed for localhost, use {phantom.connection_test: false} to disable it
  File "/usr/local/lib/python2.7/dist-packages/yandextank/core/consoleworker.py", line 375, in run
    self.core.plugins_configure()

  File "/usr/local/lib/python2.7/dist-packages/yandextank/core/tankcore.py", line 245, in plugins_configure
    plugin.configure()

  File "/usr/local/lib/python2.7/dist-packages/yandextank/plugins/Phantom/plugin.py", line 72, in configure
    self.phantom_config = self.phantom.config_file

  File "/usr/local/lib/python2.7/dist-packages/yandextank/plugins/Phantom/plugin.py", line 81, in phantom
    self._phantom.read_config()

  File "/usr/local/lib/python2.7/dist-packages/yandextank/plugins/Phantom/utils.py", line 95, in read_config
    stream.read_config()

  File "/usr/local/lib/python2.7/dist-packages/yandextank/plugins/Phantom/utils.py", line 275, in read_config
    self.address, do_test_connect, explicit_port)

  File "/usr/local/lib/python2.7/dist-packages/yandextank/common/util.py", line 555, in resolve
    raise RuntimeError(msg % address_str)

2022-05-16 20:20:56,485 [INFO] root consoleworker.py:269	Trying to clean up
2022-05-16 20:20:56,488 [INFO] yandextank.core.tankcore tankcore.py:561	Releasing lock: /var/lock/lunapark_Ae5DWZ.lock
2022-05-16 20:20:56,493 [WARNING] root consoleworker.py:408	Job number is not available yet
2022-05-16 20:20:56,495 [WARNING] root consoleworker.py:415	Job number is not available yet
2022-05-16 20:20:56,513 [DEBUG] yandextank.core.tankcore tankcore.py:367	Collecting artifacts
2022-05-16 20:20:56,516 [INFO] yandextank.core.tankcore tankcore.py:368	Artifacts dir: /var/loadtest/logs/2022-05-16_20-20-56.176872
2022-05-16 20:20:56,518 [DEBUG] yandextank.core.tankcore tankcore.py:422	Collecting file: /var/loadtest/logs/2022-05-16_20-20-56.176872/phantom_stat_I2tMAQ.log to /var/loadtest/logs/2022-05-16_20-20-56.176872/phantom_stat_I2tMAQ.log
2022-05-16 20:20:56,520 [WARNING] yandextank.core.tankcore tankcore.py:429	File already exists: /var/loadtest/logs/2022-05-16_20-20-56.176872/phantom_stat_I2tMAQ.log
2022-05-16 20:20:56,521 [DEBUG] yandextank.core.tankcore tankcore.py:422	Collecting file: /var/loadtest/logs/2022-05-16_20-20-56.176872/answ_jS3bJ9.log to /var/loadtest/logs/2022-05-16_20-20-56.176872/answ_jS3bJ9.log
2022-05-16 20:20:56,522 [WARNING] yandextank.core.tankcore tankcore.py:429	File already exists: /var/loadtest/logs/2022-05-16_20-20-56.176872/answ_jS3bJ9.log
2022-05-16 20:20:56,525 [DEBUG] yandextank.core.tankcore tankcore.py:422	Collecting file: /var/loadtest/logs/2022-05-16_20-20-56.176872/phout_zIRtLc.log to /var/loadtest/logs/2022-05-16_20-20-56.176872/phout_zIRtLc.log
2022-05-16 20:20:56,527 [WARNING] yandextank.core.tankcore tankcore.py:429	File already exists: /var/loadtest/logs/2022-05-16_20-20-56.176872/phout_zIRtLc.log
2022-05-16 20:20:56,530 [DEBUG] yandextank.core.tankcore tankcore.py:422	Collecting file: validation_error.yaml to /var/loadtest/logs/2022-05-16_20-20-56.176872/validation_error.yaml
2022-05-16 20:20:56,532 [WARNING] yandextank.core.tankcore tankcore.py:424	File not found to collect: validation_error.yaml
2022-05-16 20:20:56,534 [DEBUG] yandextank.core.tankcore tankcore.py:422	Collecting file: /var/loadtest/logs/2022-05-16_20-20-56.176872/phantom_WyEaFD.log to /var/loadtest/logs/2022-05-16_20-20-56.176872/phantom_WyEaFD.log
2022-05-16 20:20:56,535 [WARNING] yandextank.core.tankcore tankcore.py:429	File already exists: /var/loadtest/logs/2022-05-16_20-20-56.176872/phantom_WyEaFD.log
